
第4条用例报错:
HTTPConnectionPool(host='localhost', port=6777): Max retries exceeded with url: /xinxin/user/register (Caused by NewConnectionError('<urllib3.connection.HTTPConnection object at 0x000002D96206A908>: Failed to establish a new connection: [WinError 10061] 由于目标计算机积极拒绝，无法连接。'))
Traceback (most recent call last):
  File "D:\软件\lib\site-packages\urllib3\connection.py", line 160, in _new_conn
    (self._dns_host, self.port), self.timeout, **extra_kw)
  File "D:\软件\lib\site-packages\urllib3\util\connection.py", line 80, in create_connection
    raise err
  File "D:\软件\lib\site-packages\urllib3\util\connection.py", line 70, in create_connection
    sock.connect(sa)
ConnectionRefusedError: [WinError 10061] 由于目标计算机积极拒绝，无法连接。

During handling of the above exception, another exception occurred:

Traceback (most recent call last):
  File "D:\软件\lib\site-packages\urllib3\connectionpool.py", line 603, in urlopen
    chunked=chunked)
  File "D:\软件\lib\site-packages\urllib3\connectionpool.py", line 355, in _make_request
    conn.request(method, url, **httplib_request_kw)
  File "D:\软件\lib\http\client.py", line 1229, in request
    self._send_request(method, url, body, headers, encode_chunked)
  File "D:\软件\lib\http\client.py", line 1275, in _send_request
    self.endheaders(body, encode_chunked=encode_chunked)
  File "D:\软件\lib\http\client.py", line 1224, in endheaders
    self._send_output(message_body, encode_chunked=encode_chunked)
  File "D:\软件\lib\http\client.py", line 1016, in _send_output
    self.send(msg)
  File "D:\软件\lib\http\client.py", line 956, in send
    self.connect()
  File "D:\软件\lib\site-packages\urllib3\connection.py", line 183, in connect
    conn = self._new_conn()
  File "D:\软件\lib\site-packages\urllib3\connection.py", line 169, in _new_conn
    self, "Failed to establish a new connection: %s" % e)
urllib3.exceptions.NewConnectionError: <urllib3.connection.HTTPConnection object at 0x000002D96206A908>: Failed to establish a new connection: [WinError 10061] 由于目标计算机积极拒绝，无法连接。

During handling of the above exception, another exception occurred:

Traceback (most recent call last):
  File "D:\软件\lib\site-packages\requests\adapters.py", line 449, in send
    timeout=timeout
  File "D:\软件\lib\site-packages\urllib3\connectionpool.py", line 641, in urlopen
    _stacktrace=sys.exc_info()[2])
  File "D:\软件\lib\site-packages\urllib3\util\retry.py", line 399, in increment
    raise MaxRetryError(_pool, url, error or ResponseError(cause))
urllib3.exceptions.MaxRetryError: HTTPConnectionPool(host='localhost', port=6777): Max retries exceeded with url: /xinxin/user/register (Caused by NewConnectionError('<urllib3.connection.HTTPConnection object at 0x000002D96206A908>: Failed to establish a new connection: [WinError 10061] 由于目标计算机积极拒绝，无法连接。'))

During handling of the above exception, another exception occurred:

Traceback (most recent call last):
  File "D:\autoapi\python3_interface-master\main\test_api.py", line 91, in test_go_on_run
    res = RunMethod().run_main(method,url,data,header,params=data)
  File "D:\autoapi\python3_interface-master\util\runmethod.py", line 25, in run_main
    res = self.post_main(url,data,header)
  File "D:\autoapi\python3_interface-master\util\runmethod.py", line 9, in post_main
    res = requests.post(url=url,data=data,headers=header)
  File "D:\软件\lib\site-packages\requests\api.py", line 116, in post
    return request('post', url, data=data, json=json, **kwargs)
  File "D:\软件\lib\site-packages\requests\api.py", line 60, in request
    return session.request(method=method, url=url, **kwargs)
  File "D:\软件\lib\site-packages\requests\sessions.py", line 533, in request
    resp = self.send(prep, **send_kwargs)
  File "D:\软件\lib\site-packages\requests\sessions.py", line 646, in send
    r = adapter.send(request, **kwargs)
  File "D:\软件\lib\site-packages\requests\adapters.py", line 516, in send
    raise ConnectionError(e, request=request)
requests.exceptions.ConnectionError: HTTPConnectionPool(host='localhost', port=6777): Max retries exceeded with url: /xinxin/user/register (Caused by NewConnectionError('<urllib3.connection.HTTPConnection object at 0x000002D96206A908>: Failed to establish a new connection: [WinError 10061] 由于目标计算机积极拒绝，无法连接。'))

第6条用例报错:
list index out of range
Traceback (most recent call last):
  File "D:\autoapi\python3_interface-master\main\test_api.py", line 70, in test_go_on_run
    depend_response_data = self.depend_data.get_value_for_key(i)
  File "D:\autoapi\python3_interface-master\data\dependent_data.py", line 49, in get_value_for_key
    newdepend+=str([match.value for match in parse(item).find(response_data)][0])+","
IndexError: list index out of range
list index out of range
Traceback (most recent call last):
  File "D:\autoapi\python3_interface-master\main\test_api.py", line 70, in test_go_on_run
    depend_response_data = self.depend_data.get_value_for_key(i)
  File "D:\autoapi\python3_interface-master\data\dependent_data.py", line 49, in get_value_for_key
    newdepend+=str([match.value for match in parse(item).find(response_data)][0])+","
IndexError: list index out of range

第7条用例报错:
HTTPConnectionPool(host='localhost', port=6777): Max retries exceeded with url: /xinxin/user/register (Caused by NewConnectionError('<urllib3.connection.HTTPConnection object at 0x000002D96227E278>: Failed to establish a new connection: [WinError 10061] 由于目标计算机积极拒绝，无法连接。'))
Traceback (most recent call last):
  File "D:\软件\lib\site-packages\urllib3\connection.py", line 160, in _new_conn
    (self._dns_host, self.port), self.timeout, **extra_kw)
  File "D:\软件\lib\site-packages\urllib3\util\connection.py", line 80, in create_connection
    raise err
  File "D:\软件\lib\site-packages\urllib3\util\connection.py", line 70, in create_connection
    sock.connect(sa)
ConnectionRefusedError: [WinError 10061] 由于目标计算机积极拒绝，无法连接。

During handling of the above exception, another exception occurred:

Traceback (most recent call last):
  File "D:\软件\lib\site-packages\urllib3\connectionpool.py", line 603, in urlopen
    chunked=chunked)
  File "D:\软件\lib\site-packages\urllib3\connectionpool.py", line 355, in _make_request
    conn.request(method, url, **httplib_request_kw)
  File "D:\软件\lib\http\client.py", line 1229, in request
    self._send_request(method, url, body, headers, encode_chunked)
  File "D:\软件\lib\http\client.py", line 1275, in _send_request
    self.endheaders(body, encode_chunked=encode_chunked)
  File "D:\软件\lib\http\client.py", line 1224, in endheaders
    self._send_output(message_body, encode_chunked=encode_chunked)
  File "D:\软件\lib\http\client.py", line 1016, in _send_output
    self.send(msg)
  File "D:\软件\lib\http\client.py", line 956, in send
    self.connect()
  File "D:\软件\lib\site-packages\urllib3\connection.py", line 183, in connect
    conn = self._new_conn()
  File "D:\软件\lib\site-packages\urllib3\connection.py", line 169, in _new_conn
    self, "Failed to establish a new connection: %s" % e)
urllib3.exceptions.NewConnectionError: <urllib3.connection.HTTPConnection object at 0x000002D96227E278>: Failed to establish a new connection: [WinError 10061] 由于目标计算机积极拒绝，无法连接。

During handling of the above exception, another exception occurred:

Traceback (most recent call last):
  File "D:\软件\lib\site-packages\requests\adapters.py", line 449, in send
    timeout=timeout
  File "D:\软件\lib\site-packages\urllib3\connectionpool.py", line 641, in urlopen
    _stacktrace=sys.exc_info()[2])
  File "D:\软件\lib\site-packages\urllib3\util\retry.py", line 399, in increment
    raise MaxRetryError(_pool, url, error or ResponseError(cause))
urllib3.exceptions.MaxRetryError: HTTPConnectionPool(host='localhost', port=6777): Max retries exceeded with url: /xinxin/user/register (Caused by NewConnectionError('<urllib3.connection.HTTPConnection object at 0x000002D96227E278>: Failed to establish a new connection: [WinError 10061] 由于目标计算机积极拒绝，无法连接。'))

During handling of the above exception, another exception occurred:

Traceback (most recent call last):
  File "D:\autoapi\python3_interface-master\main\test_api.py", line 91, in test_go_on_run
    res = RunMethod().run_main(method,url,data,header,params=data)
  File "D:\autoapi\python3_interface-master\util\runmethod.py", line 25, in run_main
    res = self.post_main(url,data,header)
  File "D:\autoapi\python3_interface-master\util\runmethod.py", line 9, in post_main
    res = requests.post(url=url,data=data,headers=header)
  File "D:\软件\lib\site-packages\requests\api.py", line 116, in post
    return request('post', url, data=data, json=json, **kwargs)
  File "D:\软件\lib\site-packages\requests\api.py", line 60, in request
    return session.request(method=method, url=url, **kwargs)
  File "D:\软件\lib\site-packages\requests\sessions.py", line 533, in request
    resp = self.send(prep, **send_kwargs)
  File "D:\软件\lib\site-packages\requests\sessions.py", line 646, in send
    r = adapter.send(request, **kwargs)
  File "D:\软件\lib\site-packages\requests\adapters.py", line 516, in send
    raise ConnectionError(e, request=request)
requests.exceptions.ConnectionError: HTTPConnectionPool(host='localhost', port=6777): Max retries exceeded with url: /xinxin/user/register (Caused by NewConnectionError('<urllib3.connection.HTTPConnection object at 0x000002D96227E278>: Failed to establish a new connection: [WinError 10061] 由于目标计算机积极拒绝，无法连接。'))
HTTPConnectionPool(host='localhost', port=6777): Max retries exceeded with url: /xinxin/user/register (Caused by NewConnectionError('<urllib3.connection.HTTPConnection object at 0x000002D96227E278>: Failed to establish a new connection: [WinError 10061] 由于目标计算机积极拒绝，无法连接。'))
Traceback (most recent call last):
  File "D:\软件\lib\site-packages\urllib3\connection.py", line 160, in _new_conn
    (self._dns_host, self.port), self.timeout, **extra_kw)
  File "D:\软件\lib\site-packages\urllib3\util\connection.py", line 80, in create_connection
    raise err
  File "D:\软件\lib\site-packages\urllib3\util\connection.py", line 70, in create_connection
    sock.connect(sa)
ConnectionRefusedError: [WinError 10061] 由于目标计算机积极拒绝，无法连接。

During handling of the above exception, another exception occurred:

Traceback (most recent call last):
  File "D:\软件\lib\site-packages\urllib3\connectionpool.py", line 603, in urlopen
    chunked=chunked)
  File "D:\软件\lib\site-packages\urllib3\connectionpool.py", line 355, in _make_request
    conn.request(method, url, **httplib_request_kw)
  File "D:\软件\lib\http\client.py", line 1229, in request
    self._send_request(method, url, body, headers, encode_chunked)
  File "D:\软件\lib\http\client.py", line 1275, in _send_request
    self.endheaders(body, encode_chunked=encode_chunked)
  File "D:\软件\lib\http\client.py", line 1224, in endheaders
    self._send_output(message_body, encode_chunked=encode_chunked)
  File "D:\软件\lib\http\client.py", line 1016, in _send_output
    self.send(msg)
  File "D:\软件\lib\http\client.py", line 956, in send
    self.connect()
  File "D:\软件\lib\site-packages\urllib3\connection.py", line 183, in connect
    conn = self._new_conn()
  File "D:\软件\lib\site-packages\urllib3\connection.py", line 169, in _new_conn
    self, "Failed to establish a new connection: %s" % e)
urllib3.exceptions.NewConnectionError: <urllib3.connection.HTTPConnection object at 0x000002D96227E278>: Failed to establish a new connection: [WinError 10061] 由于目标计算机积极拒绝，无法连接。

During handling of the above exception, another exception occurred:

Traceback (most recent call last):
  File "D:\软件\lib\site-packages\requests\adapters.py", line 449, in send
    timeout=timeout
  File "D:\软件\lib\site-packages\urllib3\connectionpool.py", line 641, in urlopen
    _stacktrace=sys.exc_info()[2])
  File "D:\软件\lib\site-packages\urllib3\util\retry.py", line 399, in increment
    raise MaxRetryError(_pool, url, error or ResponseError(cause))
urllib3.exceptions.MaxRetryError: HTTPConnectionPool(host='localhost', port=6777): Max retries exceeded with url: /xinxin/user/register (Caused by NewConnectionError('<urllib3.connection.HTTPConnection object at 0x000002D96227E278>: Failed to establish a new connection: [WinError 10061] 由于目标计算机积极拒绝，无法连接。'))

During handling of the above exception, another exception occurred:

Traceback (most recent call last):
  File "D:\autoapi\python3_interface-master\main\test_api.py", line 91, in test_go_on_run
    res = RunMethod().run_main(method,url,data,header,params=data)
  File "D:\autoapi\python3_interface-master\util\runmethod.py", line 25, in run_main
    res = self.post_main(url,data,header)
  File "D:\autoapi\python3_interface-master\util\runmethod.py", line 9, in post_main
    res = requests.post(url=url,data=data,headers=header)
  File "D:\软件\lib\site-packages\requests\api.py", line 116, in post
    return request('post', url, data=data, json=json, **kwargs)
  File "D:\软件\lib\site-packages\requests\api.py", line 60, in request
    return session.request(method=method, url=url, **kwargs)
  File "D:\软件\lib\site-packages\requests\sessions.py", line 533, in request
    resp = self.send(prep, **send_kwargs)
  File "D:\软件\lib\site-packages\requests\sessions.py", line 646, in send
    r = adapter.send(request, **kwargs)
  File "D:\软件\lib\site-packages\requests\adapters.py", line 516, in send
    raise ConnectionError(e, request=request)
requests.exceptions.ConnectionError: HTTPConnectionPool(host='localhost', port=6777): Max retries exceeded with url: /xinxin/user/register (Caused by NewConnectionError('<urllib3.connection.HTTPConnection object at 0x000002D96227E278>: Failed to establish a new connection: [WinError 10061] 由于目标计算机积极拒绝，无法连接。'))
HTTPConnectionPool(host='localhost', port=6777): Max retries exceeded with url: /xinxin/user/register (Caused by NewConnectionError('<urllib3.connection.HTTPConnection object at 0x000002D96227E278>: Failed to establish a new connection: [WinError 10061] 由于目标计算机积极拒绝，无法连接。'))
Traceback (most recent call last):
  File "D:\软件\lib\site-packages\urllib3\connection.py", line 160, in _new_conn
    (self._dns_host, self.port), self.timeout, **extra_kw)
  File "D:\软件\lib\site-packages\urllib3\util\connection.py", line 80, in create_connection
    raise err
  File "D:\软件\lib\site-packages\urllib3\util\connection.py", line 70, in create_connection
    sock.connect(sa)
ConnectionRefusedError: [WinError 10061] 由于目标计算机积极拒绝，无法连接。

During handling of the above exception, another exception occurred:

Traceback (most recent call last):
  File "D:\软件\lib\site-packages\urllib3\connectionpool.py", line 603, in urlopen
    chunked=chunked)
  File "D:\软件\lib\site-packages\urllib3\connectionpool.py", line 355, in _make_request
    conn.request(method, url, **httplib_request_kw)
  File "D:\软件\lib\http\client.py", line 1229, in request
    self._send_request(method, url, body, headers, encode_chunked)
  File "D:\软件\lib\http\client.py", line 1275, in _send_request
    self.endheaders(body, encode_chunked=encode_chunked)
  File "D:\软件\lib\http\client.py", line 1224, in endheaders
    self._send_output(message_body, encode_chunked=encode_chunked)
  File "D:\软件\lib\http\client.py", line 1016, in _send_output
    self.send(msg)
  File "D:\软件\lib\http\client.py", line 956, in send
    self.connect()
  File "D:\软件\lib\site-packages\urllib3\connection.py", line 183, in connect
    conn = self._new_conn()
  File "D:\软件\lib\site-packages\urllib3\connection.py", line 169, in _new_conn
    self, "Failed to establish a new connection: %s" % e)
urllib3.exceptions.NewConnectionError: <urllib3.connection.HTTPConnection object at 0x000002D96227E278>: Failed to establish a new connection: [WinError 10061] 由于目标计算机积极拒绝，无法连接。

During handling of the above exception, another exception occurred:

Traceback (most recent call last):
  File "D:\软件\lib\site-packages\requests\adapters.py", line 449, in send
    timeout=timeout
  File "D:\软件\lib\site-packages\urllib3\connectionpool.py", line 641, in urlopen
    _stacktrace=sys.exc_info()[2])
  File "D:\软件\lib\site-packages\urllib3\util\retry.py", line 399, in increment
    raise MaxRetryError(_pool, url, error or ResponseError(cause))
urllib3.exceptions.MaxRetryError: HTTPConnectionPool(host='localhost', port=6777): Max retries exceeded with url: /xinxin/user/register (Caused by NewConnectionError('<urllib3.connection.HTTPConnection object at 0x000002D96227E278>: Failed to establish a new connection: [WinError 10061] 由于目标计算机积极拒绝，无法连接。'))

During handling of the above exception, another exception occurred:

Traceback (most recent call last):
  File "D:\autoapi\python3_interface-master\main\test_api.py", line 91, in test_go_on_run
    res = RunMethod().run_main(method,url,data,header,params=data)
  File "D:\autoapi\python3_interface-master\util\runmethod.py", line 25, in run_main
    res = self.post_main(url,data,header)
  File "D:\autoapi\python3_interface-master\util\runmethod.py", line 9, in post_main
    res = requests.post(url=url,data=data,headers=header)
  File "D:\软件\lib\site-packages\requests\api.py", line 116, in post
    return request('post', url, data=data, json=json, **kwargs)
  File "D:\软件\lib\site-packages\requests\api.py", line 60, in request
    return session.request(method=method, url=url, **kwargs)
  File "D:\软件\lib\site-packages\requests\sessions.py", line 533, in request
    resp = self.send(prep, **send_kwargs)
  File "D:\软件\lib\site-packages\requests\sessions.py", line 646, in send
    r = adapter.send(request, **kwargs)
  File "D:\软件\lib\site-packages\requests\adapters.py", line 516, in send
    raise ConnectionError(e, request=request)
requests.exceptions.ConnectionError: HTTPConnectionPool(host='localhost', port=6777): Max retries exceeded with url: /xinxin/user/register (Caused by NewConnectionError('<urllib3.connection.HTTPConnection object at 0x000002D96227E278>: Failed to establish a new connection: [WinError 10061] 由于目标计算机积极拒绝，无法连接。'))
