ERROR    root:print_log.py:38 HTTPConnectionPool(host='localhost', port=6777): Max retries exceeded with url: /xinxin/user/register (Caused by NewConnectionError('<urllib3.connection.HTTPConnection object at 0x000002B63B9B8B70>: Failed to establish a new connection: [WinError 10061] 由于目标计算机积极拒绝，无法连接。'))
Traceback (most recent call last):
  File "D:\软件\lib\site-packages\urllib3\connection.py", line 141, in _new_conn
    (self.host, self.port), self.timeout, **extra_kw)
  File "D:\软件\lib\site-packages\urllib3\util\connection.py", line 83, in create_connection
    raise err
  File "D:\软件\lib\site-packages\urllib3\util\connection.py", line 73, in create_connection
    sock.connect(sa)
ConnectionRefusedError: [WinError 10061] 由于目标计算机积极拒绝，无法连接。

During handling of the above exception, another exception occurred:

Traceback (most recent call last):
  File "D:\软件\lib\site-packages\urllib3\connectionpool.py", line 601, in urlopen
    chunked=chunked)
  File "D:\软件\lib\site-packages\urllib3\connectionpool.py", line 357, in _make_request
    conn.request(method, url, **httplib_request_kw)
  File "D:\软件\lib\http\client.py", line 1229, in request
    self._send_request(method, url, body, headers, encode_chunked)
  File "D:\软件\lib\http\client.py", line 1275, in _send_request
    self.endheaders(body, encode_chunked=encode_chunked)
  File "D:\软件\lib\http\client.py", line 1224, in endheaders
    self._send_output(message_body, encode_chunked=encode_chunked)
  File "D:\软件\lib\http\client.py", line 1016, in _send_output
    self.send(msg)
  File "D:\软件\lib\http\client.py", line 956, in send
    self.connect()
  File "D:\软件\lib\site-packages\urllib3\connection.py", line 166, in connect
    conn = self._new_conn()
  File "D:\软件\lib\site-packages\urllib3\connection.py", line 150, in _new_conn
    self, "Failed to establish a new connection: %s" % e)
urllib3.exceptions.NewConnectionError: <urllib3.connection.HTTPConnection object at 0x000002B63B9B8B70>: Failed to establish a new connection: [WinError 10061] 由于目标计算机积极拒绝，无法连接。

During handling of the above exception, another exception occurred:

Traceback (most recent call last):
  File "D:\软件\lib\site-packages\requests\adapters.py", line 440, in send
    timeout=timeout
  File "D:\软件\lib\site-packages\urllib3\connectionpool.py", line 639, in urlopen
    _stacktrace=sys.exc_info()[2])
  File "D:\软件\lib\site-packages\urllib3\util\retry.py", line 388, in increment
    raise MaxRetryError(_pool, url, error or ResponseError(cause))
urllib3.exceptions.MaxRetryError: HTTPConnectionPool(host='localhost', port=6777): Max retries exceeded with url: /xinxin/user/register (Caused by NewConnectionError('<urllib3.connection.HTTPConnection object at 0x000002B63B9B8B70>: Failed to establish a new connection: [WinError 10061] 由于目标计算机积极拒绝，无法连接。'))

During handling of the above exception, another exception occurred:

Traceback (most recent call last):
  File "D:\autoapi\python3_interface-master\main\test_api.py", line 84, in test_go_on_run
    res = RunMethod().run_main(method,url,data,header,params=data)
  File "D:\autoapi\python3_interface-master\util\runmethod.py", line 25, in run_main
    res = self.post_main(url,data,header)
  File "D:\autoapi\python3_interface-master\util\runmethod.py", line 9, in post_main
    res = requests.post(url=url,data=data,headers=header)
  File "D:\软件\lib\site-packages\requests\api.py", line 112, in post
    return request('post', url, data=data, json=json, **kwargs)
  File "D:\软件\lib\site-packages\requests\api.py", line 58, in request
    return session.request(method=method, url=url, **kwargs)
  File "D:\软件\lib\site-packages\requests\sessions.py", line 508, in request
    resp = self.send(prep, **send_kwargs)
  File "D:\软件\lib\site-packages\requests\sessions.py", line 618, in send
    r = adapter.send(request, **kwargs)
  File "D:\软件\lib\site-packages\requests\adapters.py", line 508, in send
    raise ConnectionError(e, request=request)
requests.exceptions.ConnectionError: HTTPConnectionPool(host='localhost', port=6777): Max retries exceeded with url: /xinxin/user/register (Caused by NewConnectionError('<urllib3.connection.HTTPConnection object at 0x000002B63B9B8B70>: Failed to establish a new connection: [WinError 10061] 由于目标计算机积极拒绝，无法连接。'))
ERROR    root:print_log.py:38 HTTPConnectionPool(host='localhost', port=6777): Max retries exceeded with url: /xinxin/user/register (Caused by NewConnectionError('<urllib3.connection.HTTPConnection object at 0x000002B63B9F6DA0>: Failed to establish a new connection: [WinError 10061] 由于目标计算机积极拒绝，无法连接。'))
Traceback (most recent call last):
  File "D:\软件\lib\site-packages\urllib3\connection.py", line 141, in _new_conn
    (self.host, self.port), self.timeout, **extra_kw)
  File "D:\软件\lib\site-packages\urllib3\util\connection.py", line 83, in create_connection
    raise err
  File "D:\软件\lib\site-packages\urllib3\util\connection.py", line 73, in create_connection
    sock.connect(sa)
ConnectionRefusedError: [WinError 10061] 由于目标计算机积极拒绝，无法连接。

During handling of the above exception, another exception occurred:

Traceback (most recent call last):
  File "D:\软件\lib\site-packages\urllib3\connectionpool.py", line 601, in urlopen
    chunked=chunked)
  File "D:\软件\lib\site-packages\urllib3\connectionpool.py", line 357, in _make_request
    conn.request(method, url, **httplib_request_kw)
  File "D:\软件\lib\http\client.py", line 1229, in request
    self._send_request(method, url, body, headers, encode_chunked)
  File "D:\软件\lib\http\client.py", line 1275, in _send_request
    self.endheaders(body, encode_chunked=encode_chunked)
  File "D:\软件\lib\http\client.py", line 1224, in endheaders
    self._send_output(message_body, encode_chunked=encode_chunked)
  File "D:\软件\lib\http\client.py", line 1016, in _send_output
    self.send(msg)
  File "D:\软件\lib\http\client.py", line 956, in send
    self.connect()
  File "D:\软件\lib\site-packages\urllib3\connection.py", line 166, in connect
    conn = self._new_conn()
  File "D:\软件\lib\site-packages\urllib3\connection.py", line 150, in _new_conn
    self, "Failed to establish a new connection: %s" % e)
urllib3.exceptions.NewConnectionError: <urllib3.connection.HTTPConnection object at 0x000002B63B9F6DA0>: Failed to establish a new connection: [WinError 10061] 由于目标计算机积极拒绝，无法连接。

During handling of the above exception, another exception occurred:

Traceback (most recent call last):
  File "D:\软件\lib\site-packages\requests\adapters.py", line 440, in send
    timeout=timeout
  File "D:\软件\lib\site-packages\urllib3\connectionpool.py", line 639, in urlopen
    _stacktrace=sys.exc_info()[2])
  File "D:\软件\lib\site-packages\urllib3\util\retry.py", line 388, in increment
    raise MaxRetryError(_pool, url, error or ResponseError(cause))
urllib3.exceptions.MaxRetryError: HTTPConnectionPool(host='localhost', port=6777): Max retries exceeded with url: /xinxin/user/register (Caused by NewConnectionError('<urllib3.connection.HTTPConnection object at 0x000002B63B9F6DA0>: Failed to establish a new connection: [WinError 10061] 由于目标计算机积极拒绝，无法连接。'))

During handling of the above exception, another exception occurred:

Traceback (most recent call last):
  File "D:\autoapi\python3_interface-master\main\test_api.py", line 84, in test_go_on_run
    res = RunMethod().run_main(method,url,data,header,params=data)
  File "D:\autoapi\python3_interface-master\util\runmethod.py", line 25, in run_main
    res = self.post_main(url,data,header)
  File "D:\autoapi\python3_interface-master\util\runmethod.py", line 9, in post_main
    res = requests.post(url=url,data=data,headers=header)
  File "D:\软件\lib\site-packages\requests\api.py", line 112, in post
    return request('post', url, data=data, json=json, **kwargs)
  File "D:\软件\lib\site-packages\requests\api.py", line 58, in request
    return session.request(method=method, url=url, **kwargs)
  File "D:\软件\lib\site-packages\requests\sessions.py", line 508, in request
    resp = self.send(prep, **send_kwargs)
  File "D:\软件\lib\site-packages\requests\sessions.py", line 618, in send
    r = adapter.send(request, **kwargs)
  File "D:\软件\lib\site-packages\requests\adapters.py", line 508, in send
    raise ConnectionError(e, request=request)
requests.exceptions.ConnectionError: HTTPConnectionPool(host='localhost', port=6777): Max retries exceeded with url: /xinxin/user/register (Caused by NewConnectionError('<urllib3.connection.HTTPConnection object at 0x000002B63B9F6DA0>: Failed to establish a new connection: [WinError 10061] 由于目标计算机积极拒绝，无法连接。'))
ERROR    root:print_log.py:38 Expecting value: line 1 column 1 (char 0)
Traceback (most recent call last):
  File "D:\autoapi\python3_interface-master\main\test_api.py", line 102, in test_go_on_run
    res = RunMethod().run_main(method,url,data,header,params=data)
  File "D:\autoapi\python3_interface-master\util\runmethod.py", line 27, in run_main
    res = self.get_main(url,params,header)
  File "D:\autoapi\python3_interface-master\util\runmethod.py", line 20, in get_main
    return res.json()
  File "D:\软件\lib\site-packages\requests\models.py", line 892, in json
    return complexjson.loads(self.text, **kwargs)
  File "D:\软件\lib\site-packages\simplejson\__init__.py", line 525, in loads
    return _default_decoder.decode(s)
  File "D:\软件\lib\site-packages\simplejson\decoder.py", line 370, in decode
    obj, end = self.raw_decode(s)
  File "D:\软件\lib\site-packages\simplejson\decoder.py", line 400, in raw_decode
    return self.scan_once(s, idx=_w(s, idx).end())
simplejson.errors.JSONDecodeError: Expecting value: line 1 column 1 (char 0)
ERROR    root:print_log.py:38 HTTPConnectionPool(host='localhost', port=6777): Max retries exceeded with url: /xinxin/user/register (Caused by NewConnectionError('<urllib3.connection.HTTPConnection object at 0x000002B63BAF1278>: Failed to establish a new connection: [WinError 10061] 由于目标计算机积极拒绝，无法连接。'))
Traceback (most recent call last):
  File "D:\软件\lib\site-packages\urllib3\connection.py", line 141, in _new_conn
    (self.host, self.port), self.timeout, **extra_kw)
  File "D:\软件\lib\site-packages\urllib3\util\connection.py", line 83, in create_connection
    raise err
  File "D:\软件\lib\site-packages\urllib3\util\connection.py", line 73, in create_connection
    sock.connect(sa)
ConnectionRefusedError: [WinError 10061] 由于目标计算机积极拒绝，无法连接。

During handling of the above exception, another exception occurred:

Traceback (most recent call last):
  File "D:\软件\lib\site-packages\urllib3\connectionpool.py", line 601, in urlopen
    chunked=chunked)
  File "D:\软件\lib\site-packages\urllib3\connectionpool.py", line 357, in _make_request
    conn.request(method, url, **httplib_request_kw)
  File "D:\软件\lib\http\client.py", line 1229, in request
    self._send_request(method, url, body, headers, encode_chunked)
  File "D:\软件\lib\http\client.py", line 1275, in _send_request
    self.endheaders(body, encode_chunked=encode_chunked)
  File "D:\软件\lib\http\client.py", line 1224, in endheaders
    self._send_output(message_body, encode_chunked=encode_chunked)
  File "D:\软件\lib\http\client.py", line 1016, in _send_output
    self.send(msg)
  File "D:\软件\lib\http\client.py", line 956, in send
    self.connect()
  File "D:\软件\lib\site-packages\urllib3\connection.py", line 166, in connect
    conn = self._new_conn()
  File "D:\软件\lib\site-packages\urllib3\connection.py", line 150, in _new_conn
    self, "Failed to establish a new connection: %s" % e)
urllib3.exceptions.NewConnectionError: <urllib3.connection.HTTPConnection object at 0x000002B63BAF1278>: Failed to establish a new connection: [WinError 10061] 由于目标计算机积极拒绝，无法连接。

During handling of the above exception, another exception occurred:

Traceback (most recent call last):
  File "D:\软件\lib\site-packages\requests\adapters.py", line 440, in send
    timeout=timeout
  File "D:\软件\lib\site-packages\urllib3\connectionpool.py", line 639, in urlopen
    _stacktrace=sys.exc_info()[2])
  File "D:\软件\lib\site-packages\urllib3\util\retry.py", line 388, in increment
    raise MaxRetryError(_pool, url, error or ResponseError(cause))
urllib3.exceptions.MaxRetryError: HTTPConnectionPool(host='localhost', port=6777): Max retries exceeded with url: /xinxin/user/register (Caused by NewConnectionError('<urllib3.connection.HTTPConnection object at 0x000002B63BAF1278>: Failed to establish a new connection: [WinError 10061] 由于目标计算机积极拒绝，无法连接。'))

During handling of the above exception, another exception occurred:

Traceback (most recent call last):
  File "D:\autoapi\python3_interface-master\main\test_api.py", line 84, in test_go_on_run
    res = RunMethod().run_main(method,url,data,header,params=data)
  File "D:\autoapi\python3_interface-master\util\runmethod.py", line 25, in run_main
    res = self.post_main(url,data,header)
  File "D:\autoapi\python3_interface-master\util\runmethod.py", line 9, in post_main
    res = requests.post(url=url,data=data,headers=header)
  File "D:\软件\lib\site-packages\requests\api.py", line 112, in post
    return request('post', url, data=data, json=json, **kwargs)
  File "D:\软件\lib\site-packages\requests\api.py", line 58, in request
    return session.request(method=method, url=url, **kwargs)
  File "D:\软件\lib\site-packages\requests\sessions.py", line 508, in request
    resp = self.send(prep, **send_kwargs)
  File "D:\软件\lib\site-packages\requests\sessions.py", line 618, in send
    r = adapter.send(request, **kwargs)
  File "D:\软件\lib\site-packages\requests\adapters.py", line 508, in send
    raise ConnectionError(e, request=request)
requests.exceptions.ConnectionError: HTTPConnectionPool(host='localhost', port=6777): Max retries exceeded with url: /xinxin/user/register (Caused by NewConnectionError('<urllib3.connection.HTTPConnection object at 0x000002B63BAF1278>: Failed to establish a new connection: [WinError 10061] 由于目标计算机积极拒绝，无法连接。'))